Workbook

Sheet Cover
B2: Infosys Limited
B3: Equity Research & DCF Valuation Model
B5: NSE: INFY | BSE: 500209 | Sector: IT Services | H5: Prepared by: Rajeev Kumar
H6: ="Valuation Date: "&TEXT(TODAY(), "DD MMM YYYY") -> Valuation Date: 10 Sep 2026
B7: BUY | Target Price: ₹2,035 | Current Price: ₹1,600 | Upside: 27%
B10: INVESTMENT THESIS
B12: ◉ BFSI Recovery + GenAI Tailwind: Deal pipeline recovering in BFSI vertical (35% of revenue) with mega-deal ramp-ups expected in FY2026E. Management's GenAI-focused service offerings position Infosys ahead of peers in the next technology cycle.
B14: ◉ Margin Expansion Story: EBITDA margins expected to expand from 24.5% in FY2025E to 26.5% by FY2029E driven by operating leverage, pyramid optimisation, and declining sub-contracting costs.
B16: ◉ Capital Return Underappreciated: ₹55% dividend payout + periodic buybacks (₹5,000 Cr in FY2026E, FY2028E) implies total shareholder yield of ~4-5% annually — a floor on downside even in bear scenarios.
B20: KEY MODEL OUTPUTS | H20: MODEL STRUCTURE
B22: Intrinsic Value (Exit Multiple) | D22: ="₹"&TEXT(DCF_Valuation!B65,"##,##0")&" per share" -> ₹2,035 per share | H22: Assumptions - All model drivers and inputs
B23: Intrinsic Value (GGM) | D23: ="₹"&TEXT(DCF_Valuation!B64,"##,##0")&" per share" -> ₹959 per share | H23: Historical - FY2020-FY2024 actuals (IFRS)
B24: Enterprise Value | D24: ="₹"&TEXT(DCF_Valuation!B50,"##,##0")&" Cr" -> ₹8,16,149 Cr | H24: IS_Forecast - 5-Year P&L projection
B25: FY2029E Revenue | D25: ="₹"&TEXT(IS_Forecast!G4,"##,##0")&" Cr" -> ₹2,06,527 Cr | H25: BS_Forecast - Balance Sheet with plug
B26: FY2029E EBITDA Margin | D26: =TEXT(IS_Forecast!G11,"0.0%") -> 26.5% | H26: CFS_Forecast - Cash Flow Statement
B27: FY2029E FCF | D27: ="₹"&TEXT(CFS_Forecast!G28,"##,##0")&" Cr" -> ₹38,332 Cr | H27: DCF_Valuation - FCFF DCF + Sensitivity
B28: WACC | D28: =TEXT(Assumptions!B49,"0.0%") -> 12.5%
B29: Terminal Growth Rate | D29: =TEXT(Assumptions!B50,"0.0%") -> 4.5%
B34: KEY RISKS
B35: Downside risks include: (1) Prolonged weakness in US discretionary IT spend, (2) Margin compression from wage inflation and visa costs, (3) Client concentration in BFSI vertical, (4) Currency headwinds from INR appreciation vs USD.
B37: This model is prepared for educational and portfolio purposes only. All estimates are the author's own and do not constitute investment advice. Data sourced from company filings, Bombay Stock Exchange, and public disclosures.

Sheet Assumptions
A1: MODEL ASSUMPTIONS — INFOSYS LTD
A2: All figures in ₹ Crores unless stated
A4: Revenue Growth Assumptions
A5: FY2025E Revenue Growth Rate | B5: =CHOOSE(MATCH($B$68,{"Bear Case","Base Case","Bull Case"},0),Scenarios!B7,Scenarios!C7,Scenarios!D7) -> 0.035 | C5: Muted discretionary; guided 1-3% CC
A6: FY2026E Revenue Growth Rate | B6: =CHOOSE(MATCH($B$68,{"Bear Case","Base Case","Bull Case"},0),Scenarios!B8,Scenarios!C8,Scenarios!D8) -> 0.06 | C6: BFSI recovery; medga deal ramp-ups
A7: FY2027E Revenue Growth Rate | B7: =CHOOSE(MATCH($B$68,{"Bear Case","Base Case","Bull Case"},0),Scenarios!B9,Scenarios!C9,Scenarios!D9) -> 0.075 | C7: GenAi services acceleration
A8: FY2028E Revenue Growth Rate | B8: =CHOOSE(MATCH($B$68,{"Bear Case","Base Case","Bull Case"},0),Scenarios!B10,Scenarios!C10,Scenarios!D10) -> 0.07 | C8: Steady-state digital transformation
A9: FY2029E Revenue Growth Rate | B9: =CHOOSE(MATCH($B$68,{"Bear Case","Base Case","Bull Case"},0),Scenarios!B11,Scenarios!C11,Scenarios!D11) -> 0.065 | C9: Maturation; base effect deceleration
A10: Base Revenue (FY2024A) | B10: 153670 | C10: Actual FY2024 revenue (₹ Cr)
A12: Margin Assumptions | B12: FY2025E | C12: FY2026E | D12: FY2027E | E12: FY2028E | F12: FY2029E
A13: Gross Margin | B13: 0.29 | C13: 0.295 | D13: 0.3 | E13: 0.302 | F13: 0.305
A14: EBITDA Margin | B14: =CHOOSE(MATCH($B$68,{"Bear Case","Base Case","Bull Case"},0),Scenarios!B14,Scenarios!C14,Scenarios!D14) -> 0.245 | C14: =CHOOSE(MATCH($B$68,{"Bear Case","Base Case","Bull Case"},0),Scenarios!B15,Scenarios!C15,Scenarios!D15) -> 0.252 | D14: =CHOOSE(MATCH($B$68,{"Bear Case","Base Case","Bull Case"},0),Scenarios!B16,Scenarios!C16,Scenarios!D16) -> 0.258 | E14: =CHOOSE(MATCH($B$68,{"Bear Case","Base Case","Bull Case"},0),Scenarios!B17,Scenarios!C17,Scenarios!D17) -> 0.262 | F14: =CHOOSE(MATCH($B$68,{"Bear Case","Base Case","Bull Case"},0),Scenarios!B18,Scenarios!C18,Scenarios!D18) -> 0.265
A15: D&A(% of Revenue) | B15: 0.03 | C15: 0.03 | D15: 0.03 | E15: 0.029 | F15: 0.029
A16: EBIT Margin | B16: 0.215 | C16: 0.222 | D16: 0.228 | E16: 0.233 | F16: 0.236
A17: Other Income(₹Cr) | B17: 3650 | C17: 3900 | D17: 4150 | E17: 4400 | F17: 4650
A19: Tax & Cost Assumptions
A20: Effective Tax rate | B20: 0.26 | C20: SEZ expirations, steady-state
A21: Stock-Based Compensation (FY25E start) | B21: 720 | C21: Grows ~₹40-₹60 Cr/yr
A22: SBC Annual Increment | B22: 40 | C22: ₹ Cr per year
A24: CapEx & Depreciation | B24: FY2025E | C24: FY2026E | D24: FY2027E | E24: FY2028E | F24: FY2029E
A25: CapEx (% of Revenue) | B25: 0.027 | C25: 0.026 | D25: 0.026 | E25: 0.025 | F25: 0.025
A26: D&A (% of Revenue) | B26: 0.03 | C26: 0.03 | D26: 0.03 | E26: 0.029 | F26: 0.029
A28: Working Capital Assumptions
A29: Days Sales Outstanding (DSO) | B29: 67 | C29: Days; historical range 65-69
A30: Days Payable Outstanding (DPO) | B30: 20 | C30: Days; historical range 19-21
A31: Unbilled Rev & Other CA (%of Rev) | B31: 0.068 | C31: Historical 6.5%-7.0%
A32: Other CL Grwoth Rate | B32: 0.035 | C32: Approx growth
A34: Capital Return Assumptions
A35: Dividend Payout Ratio (% of NI) | B35: 0.55 | C35: Historical avg ~50-60%
A36: FY2025E Buyback | B36: 0 | C36: ₹ Cr
A37: FY2026E Buyback | B37: 5000 | C37: ₹ Cr
A38: FY2027E Buyback | B38: 0 | C38: ₹ Cr
A39: FY2028E Buyback | B39: 5000 | C39: ₹ Cr
A40: FY2029E Buyback | B40: 0 | C40: ₹ Cr
A42: DCF Valuation Assumptions
A43: Risk Free Rate (India 10Y G-Sec) | B43: 0.07 | C43: As of valuation date
A44: Equity Risk Premium | B44: 0.065 | C44: India ERP (Damodram)
A45: Beta (levered) | B45: 0.85 | C45: 5-year monthly regression vs Nifty 50
A46: Cost of Equity (Ke) | B46: =B43+B45*B44 -> 0.12525 | C46: =B43 + B45 * B44
A47: Cost of Debt (pre-tax) | B47: 0 | C47: Zero financial debt
...

Sheet Scenarios
A1: SCENARIO ANALYSIS - INFOSYS LTD
A2: All figures in ₹ Crores unless stated
B4: Bear Case | C4: Base Case | D4: Bull Case
A6: REVENUE GROWTH
A7: FY2025E | B7: 0.02 | C7: 0.035 | D7: 0.045
A8: FY2026E | B8: 0.04 | C8: 0.06 | D8: 0.08
A9: FY2027E | B9: 0.05 | C9: 0.075 | D9: 0.1
A10: FY2028E | B10: 0.045 | C10: 0.07 | D10: 0.09
A11: FY2029E | B11: 0.04 | C11: 0.065 | D11: 0.08
A13: EBITDA MARGINS
A14: FY2025E | B14: 0.225 | C14: 0.245 | D14: 0.26
A15: FY2026E | B15: 0.23 | C15: 0.252 | D15: 0.268
A16: FY2027E | B16: 0.235 | C16: 0.258 | D16: 0.275
A17: FY2028E | B17: 0.238 | C17: 0.262 | D17: 0.28
A18: FY2029E | B18: 0.24 | C18: 0.265 | D18: 0.285
A20: DCF ASSUMPTIONS
A21: Terminal Growth Rate | B21: 0.035 | C21: 0.045 | D21: 0.055
A22: Exit EV/EBITDA Multiple | B22: 18 | C22: 22 | D22: 26
A23: WACC | B23: 0.135 | C23: 0.12525 | D23: 0.115
A26: SCENARIO OUTPUT SUMMARY
A27: Metric | B27: Bear Case | C27: Base Case | D27: Bull Case
A28: FY2029E Revenue (₹ Cr) | B28: 186020.81 | C28: 206527.15 | D28: 224580.52
A29: FY2029E EBITDA Margin | B29: 0.24 | C29: 0.27 | D29: 0.29
A30: FY2029E FCFF (₹ Cr) | B30: 28233 | C30: 34171 | D30: 39857
A31: Intrinsic Value - Exit Multiple (₹) | B31: 1386.06 | C31: 2034.86 | D31: 2821.08
A32: Upside / ( Downside) vs CMP | B32: -0.13 | C32: 0.27 | D32: 0.76

Sheet Historical
A1: HISTORICAL FINANCIALS — INFOSYS LTD
A2: ₹ Crores, IFRS Consolidated
A3: INCOME STATEMENT | B3: FY2020 | C3: FY2021 | D3: FY2022 | E3: FY2023 | F3: FY2024
A4: Revenue | B4: 90791 | C4: 100472 | D4: 121641 | E4: 146767 | F4: 153670
A5: YoY Growth (%) | B5: 0.098 | C5: =(C4-B4)/B4 -> 0.10662951 | D5: =(D4-C4)/C4 -> 0.21069552 | E5: =(E4-D4)/D4 -> 0.20655864 | F5: =(F4-E4)/E4 -> 0.047033734
A6: Cost of Revenues | B6: -63055 | C6: -69125 | D6: -85750 | E6: -105675 | F6: -109610
A7: Gross Profit | B7: =B4+B6 -> 27736 | C7: =C4+C6 -> 31347 | D7: =D4+D6 -> 35891 | E7: =E4+E6 -> 41092 | F7: =F4+F6 -> 44060
A8: Gross Margin (%) | B8: =B7/B4 -> 0.30549284 | C8: =C7/C4 -> 0.31199737 | D8: =D7/D4 -> 0.29505677 | E8: =E7/E4 -> 0.27998119 | F8: =F7/F4 -> 0.28671829
A9: SG&A & Other OpEx | B9: -8358 | C9: -6662 | D9: -8353 | E9: -11060 | F9: -11545
A10: EBITDA | B10: =B7+B9 -> 19378 | C10: =C7+C9 -> 24685 | D10: =D7+D9 -> 27538 | E10: =E7+E9 -> 30032 | F10: =F7+F9 -> 32515
A11: EBITDA Margin (%) | B11: =B10/B4 -> 0.21343525 | C11: =C10/C4 -> 0.24569034 | D11: =D10/D4 -> 0.22638748 | E11: =E10/E4 -> 0.20462366 | F11: =F10/F4 -> 0.21158977
A12: Depreciation & Amortization | B12: -2871 | C12: -3370 | D12: -3775 | E12: -4213 | F12: -4490
A13: EBIT | B13: =B10+B12 -> 16507 | C13: =C10+C12 -> 21315 | D13: =D10+D12 -> 23763 | E13: =E10+E12 -> 25819 | F13: =F10+F12 -> 28025
A14: EBIT Margin (%) | B14: =B13/B4 -> 0.18181318 | C14: =C13/C4 -> 0.21214866 | D14: =D13/D4 -> 0.19535354 | E14: =E13/E4 -> 0.17591829 | F14: =F13/F4 -> 0.18237132
A15: Other Income (net) | B15: 2877 | C15: 2620 | D15: 2780 | E15: 3200 | F15: 3450
A16: Profit Before Tax | B16: =B13+B15 -> 19384 | C16: =C13+C15 -> 23935 | D16: =D13+D15 -> 26543 | E16: =E13+E15 -> 29019 | F16: =F13+F15 -> 31475
A17: Income Tax | B17: -5661 | C17: -7954 | D17: -8208 | E17: -9124 | F17: -9732
A18: Effective Tax Rate (%) | B18: =-B17/B16 -> 0.29204499 | C18: =-C17/C16 -> 0.33231669 | D18: =-D17/D16 -> 0.30923407 | E18: =-E17/E16 -> 0.31441469 | F18: =-F17/F16 -> 0.30919778
A19: Net Income | B19: =B16+B17 -> 13723 | C19: =C16+C17 -> 15981 | D19: =D16+D17 -> 18335 | E19: =E16+E17 -> 19895 | F19: =F16+F17 -> 21743
A20: Net Margin (%) | B20: =B19/B4 -> 0.15114934 | C20: =C19/C4 -> 0.15905924 | D20: =D19/D4 -> 0.15073043 | E20: =E19/E4 -> 0.135555 | F20: =F19/F4 -> 0.14149151
A22: BALANCE SHEET | B22: FY2020 | C22: FY2021 | D22: FY2022 | E22: FY2023 | F22: FY2024
A23: ASSETS
A24: Cash & Cash Equivalents | B24: 17936 | C24: 22002 | D24: 17491 | E24: 12547 | F24: 15003
A25: Current Investments | B25: 6390 | C25: 8493 | D25: 12406 | E25: 9998 | F25: 13315
A26: Trade Receivables | B26: 18604 | C26: 19975 | D26: 24537 | E26: 27558 | F26: 28840
A27: Unbilled Revenue & Other CA | B27: 6200 | C27: 7300 | D27: 8400 | E27: 9800 | F27: 10500
A28: Total Current Assets | B28: =SUM(B24:B27) -> 49130 | C28: =SUM(C24:C27) -> 57770 | D28: =SUM(D24:D27) -> 62834 | E28: =SUM(E24:E27) -> 59903 | F28: =SUM(F24:F27) -> 67658
A29: PP&E (net) | B29: 12450 | C29: 12850 | D29: 13750 | E29: 14700 | F29: 14500
A30: Right-of-Use Assets | B30: 5800 | C30: 5400 | D30: 5100 | E30: 5800 | F30: 6200
A31: Goodwill & Intangibles | B31: 4438 | C31: 5650 | D31: 7306 | E31: 7100 | F31: 6814
A32: Other Non-Current Assets | B32: 5250 | C32: 7833 | D32: 10850 | E32: 20305 | F32: 22200
A33: Total Non-Current Assets | B33: =SUM(B29:B32) -> 27938 | C33: =SUM(C29:C32) -> 31733 | D33: =SUM(D29:D32) -> 37006 | E33: =SUM(E29:E32) -> 47905 | F33: =SUM(F29:F32) -> 49714
A34: TOTAL ASSETS | B34: =B28+B33 -> 77068 | C34: =C28+C33 -> 89503 | D34: =D28+D33 -> 99840 | E34: =E28+E33 -> 107808 | F34: =F28+F33 -> 117372
A36: LIABILITIES
A37: Trade Payables | B37: 3680 | C37: 4100 | D37: 4920 | E37: 5620 | F37: 5900
A38: Other Current Liabilities | B38: 5420 | C38: 7500 | D38: 14180 | E38: 17780 | F38: 19900
A39: Total Current Liabilities | B39: =B37+B38 -> 9100 | C39: =C37+C38 -> 11600 | D39: =D37+D38 -> 19100 | E39: =E37+E38 -> 23400 | F39: =F37+F38 -> 25800
A40: Lease Liabilities (NCL) | B40: 2500 | C40: 4100 | D40: 5900 | E40: 7500 | F40: 8200
A41: Other Non-Current Liabilities | B41: 520 | C41: 688 | D41: 2403 | E41: 4708 | F41: 7555
A42: Total Non-Current Liabilities | B42: =B40+B41 -> 3020 | C42: =C40+C41 -> 4788 | D42: =D40+D41 -> 8303 | E42: =E40+E41 -> 12208 | F42: =F40+F41 -> 15755
...

Sheet IS_Forecast
A1: INCOME STATEMENT FORECAST
A2: ₹ Crores
B3: FY2024A | C3: FY2025E | D3: FY2026E | E3: FY2027E | F3: FY2028E | G3: FY2029E
A4: Revenue | B4: =Historical!F4 -> 153670 | C4: =B4*(1+Assumptions!B5) -> 159048.45 | D4: =C4*(1+Assumptions!B6) -> 168591.36 | E4: =D4*(1+Assumptions!B7) -> 181235.71 | F4: =E4*(1+Assumptions!B8) -> 193922.21 | G4: =F4*(1+Assumptions!B9) -> 206527.15
A5: YoY Growth (%) | B5: =Historical!F5 -> 0.047033734 | C5: =Assumptions!B5 -> 0.035 | D5: =Assumptions!B6 -> 0.06 | E5: =Assumptions!B7 -> 0.075 | F5: =Assumptions!B8 -> 0.07 | G5: =Assumptions!B9 -> 0.065
A6: Cost of Revenues | B6: =Historical!F6 -> -109610 | C6: =-C4*(1-Assumptions!B13) -> -112924.4 | D6: =-D4*(1-Assumptions!C13) -> -118856.91 | E6: =-E4*(1-Assumptions!D13) -> -126865 | F6: =-F4*(1-Assumptions!E13) -> -135357.7 | G6: =-G4*(1-Assumptions!F13) -> -143536.37
A7: Gross Profit | B7: =B4+B6 -> 44060 | C7: =C4+C6 -> 46124.05 | D7: =D4+D6 -> 49734.45 | E7: =E4+E6 -> 54370.713 | F7: =F4+F6 -> 58564.507 | G7: =G4+G6 -> 62990.781
A8: Gross Margin (%) | B8: =B7/B4 -> 0.28671829 | C8: =C7/C4 -> 0.29 | D8: =D7/D4 -> 0.295 | E8: =E7/E4 -> 0.3 | F8: =F7/F4 -> 0.302 | G8: =G7/G4 -> 0.305
A9: SG&A & Other OpEx | B9: =Historical!F9 -> -11545 | C9: =-(C7-C4*Assumptions!B14) -> -7157.1803 | D9: =-(D7-D4*Assumptions!C14) -> -7249.4284 | E9: =-(E7-E4*Assumptions!D14) -> -7611.8998 | F9: =-(F7-F4*Assumptions!E14) -> -7756.8883 | G9: =-(G7-G4*Assumptions!F14) -> -8261.0861
A10: EBITDA | B10: =B7+B9 -> 32515 | C10: =C7+C9 -> 38966.87 | D10: =D7+D9 -> 42485.022 | E10: =E7+E9 -> 46758.813 | F10: =F7+F9 -> 50807.619 | G10: =G7+G9 -> 54729.695
A11: EBITDA Margin (%) | B11: =B10/B4 -> 0.21158977 | C11: =C10/C4 -> 0.245 | D11: =D10/D4 -> 0.252 | E11: =E10/E4 -> 0.258 | F11: =F10/F4 -> 0.262 | G11: =G10/G4 -> 0.265
A12: Depreciation & Amortization | B12: =Historical!F12 -> -4490 | C12: =-C4*Assumptions!B26 -> -4771.4535 | D12: =-D4*Assumptions!C26 -> -5057.7407 | E12: =-E4*Assumptions!D26 -> -5437.0713 | F12: =-F4*Assumptions!E26 -> -5623.744 | G12: =-G4*Assumptions!F26 -> -5989.2874
A13: EBIT | B13: =B10+B12 -> 28025 | C13: =C10+C12 -> 34195.417 | D13: =D10+D12 -> 37427.281 | E13: =E10+E12 -> 41321.742 | F13: =F10+F12 -> 45183.875 | G13: =G10+G12 -> 48740.408
A14: EBIT Margin (%) | B14: =B13/B4 -> 0.18237132 | C14: =C13/C4 -> 0.215 | D14: =D13/D4 -> 0.222 | E14: =E13/E4 -> 0.228 | F14: =F13/F4 -> 0.233 | G14: =G13/G4 -> 0.236
A15: Other Income (net) | B15: =Historical!F15 -> 3450 | C15: =Assumptions!B17 -> 3650 | D15: =Assumptions!C17 -> 3900 | E15: =Assumptions!D17 -> 4150 | F15: =Assumptions!E17 -> 4400 | G15: =Assumptions!F17 -> 4650
A16: Profit Before Tax | B16: =B13+B15 -> 31475 | C16: =C13+C15 -> 37845.417 | D16: =D13+D15 -> 41327.281 | E16: =E13+E15 -> 45471.742 | F16: =F13+F15 -> 49583.875 | G16: =G13+G15 -> 53390.408
A17: Income Tax | B17: =Historical!F17 -> -9732 | C17: =-C16*Assumptions!B20 -> -9839.8084 | D17: =-D16*Assumptions!B20 -> -10745.093 | E17: =-E16*Assumptions!B20 -> -11822.653 | F17: =-F16*Assumptions!B20 -> -12891.807 | G17: =-G16*Assumptions!B20 -> -13881.506
A18: Effective Tax Rate (%) | B18: =-B17/B16 -> 0.30919778 | C18: =Assumptions!B20 -> 0.26 | D18: =Assumptions!B20 -> 0.26 | E18: =Assumptions!B20 -> 0.26 | F18: =Assumptions!B20 -> 0.26 | G18: =Assumptions!B20 -> 0.26
A19: Net Income | B19: =B16+B17 -> 21743 | C19: =C16+C17 -> 28005.608 | D19: =D16+D17 -> 30582.188 | E19: =E16+E17 -> 33649.089 | F19: =F16+F17 -> 36692.067 | G19: =G16+G17 -> 39508.902
A20: Net Margin (%) | B20: =B19/B4 -> 0.14149151 | C20: =C19/C4 -> 0.17608225 | D20: =D19/D4 -> 0.18139832 | E20: =E19/E4 -> 0.18566478 | F20: =F19/F4 -> 0.18921024 | G20: =G19/G4 -> 0.19130125

Sheet BS_Forecast
A1: BALANCE SHEET FORECAST
A2: ₹ Crores
B3: FY2024A | C3: FY2025E | D3: FY2026E | E3: FY2027E | F3: FY2028E | G3: FY2029E
A4: ASSETS
A5: Cash & Cash Equivalents | B5: 15003 | C5: =C24+C29-(C6+C7+C8)-C14 -> 26893.618 | D5: =D24+D29-(D6+D7+D8)-D14 -> 33353.992 | E5: =E24+E29-(E6+E7+E8)-E14 -> 45486.541 | F5: =F24+F29-(F6+F7+F8)-F14 -> 54005.731 | G5: =G24+G29-(G6+G7+G8)-G14 -> 68638.879
A6: Current Investments | B6: 13315 | C6: =B6*(1+Assumptions!B56) -> 14380.2 | D6: =C6*(1+Assumptions!C56) -> 15530.616 | E6: =D6*(1+Assumptions!D56) -> 16773.065 | F6: =E6*(1+Assumptions!E56) -> 18114.911 | G6: =F6*(1+Assumptions!F56) -> 19564.103
A7: Trade Receivables | B7: 28840 | C7: =IS_Forecast!C4*Assumptions!B29/365 -> 29195.195 | D7: =IS_Forecast!D4*Assumptions!B29/365 -> 30946.907 | E7: =IS_Forecast!E4*Assumptions!B29/365 -> 33267.925 | F7: =IS_Forecast!F4*Assumptions!B29/365 -> 35596.679 | G7: =IS_Forecast!G4*Assumptions!B29/365 -> 37910.464
A8: Unbilled Revenue & Other CA | B8: 10500 | C8: =IS_Forecast!C4*Assumptions!B31 -> 10815.295 | D8: =IS_Forecast!D4 * Assumptions!B31 -> 11464.212 | E8: =IS_Forecast!E4 * Assumptions!B31 -> 12324.028 | F8: =IS_Forecast!F4 * Assumptions!B31 -> 13186.71 | G8: =IS_Forecast!G4 * Assumptions!B31 -> 14043.846
A9: Total Current Assets | B9: 67658 | C9: =SUM(C5:C8) -> 81284.307 | D9: =SUM(D5:D8) -> 91295.726 | E9: =SUM(E5:E8) -> 107851.56 | F9: =SUM(F5:F8) -> 120904.03 | G9: =SUM(G5:G8) -> 140157.29
A10: PP&E (net) | B10: 14500 | C10: =B10-CFS_Forecast!C12+IS_Forecast!C12 -> 14022.855 | D10: =C10-CFS_Forecast!D12+IS_Forecast!D12 -> 13348.489 | E10: =D10-CFS_Forecast!E12+IS_Forecast!E12 -> 12623.546 | F10: =E10-CFS_Forecast!F12+IS_Forecast!F12 -> 11847.858 | G10: =F10-CFS_Forecast!G12+IS_Forecast!G12 -> 11021.749
A11: ROU Assets | B11: 6200 | C11: =Assumptions!B57 -> 6300 | D11: =Assumptions!C57 -> 6400 | E11: =Assumptions!D57 -> 6400 | F11: =Assumptions!E57 -> 6500 | G11: =Assumptions!F57 -> 6500
A12: Goodwill & Intangibles | B12: 6814 | C12: =Assumptions!B58 -> 6500 | D12: =Assumptions!C58 -> 6200 | E12: =Assumptions!D58 -> 5900 | F12: =Assumptions!E58 -> 5650 | G12: =Assumptions!F58 -> 5400
A13: Other Non-Current Assets | B13: 22200 | C13: =Assumptions!B59 -> 23100 | D13: =Assumptions!C59 -> 24200 | E13: =Assumptions!D59 -> 25400 | F13: =Assumptions!E59 -> 26700 | G13: =Assumptions!F59 -> 28100
A14: Total Non-Current Assets | B14: 49714 | C14: =SUM(C10:C13) -> 49922.855 | D14: =SUM(D10:D13) -> 50148.489 | E14: =SUM(E10:E13) -> 50323.546 | F14: =SUM(F10:F13) -> 50697.858 | G14: =SUM(G10:G13) -> 51021.749
A15: TOTAL ASSETS | B15: 117372 | C15: =C9+C14 -> 131207.16 | D15: =D9+D14 -> 141444.22 | E15: =E9+E14 -> 158175.11 | F15: =F9+F14 -> 171601.89 | G15: =G9+G14 -> 191179.04
A17: LIABILITIES
A18: Trade Payables | B18: 5900 | C18: =-IS_Forecast!C6*Assumptions!B30/365 -> 6187.6383 | D18: =-IS_Forecast!D6*Assumptions!B30/365 -> 6512.7072 | E18: =-IS_Forecast!E6*Assumptions!B30/365 -> 6951.5066 | F18: =-IS_Forecast!F6*Assumptions!B30/365 -> 7416.8604 | G18: =-IS_Forecast!G6*Assumptions!B30/365 -> 7865.0066
A19: Other Current Liabilities | B19: 19900 | C19: =Assumptions!B60 -> 20400 | D19: =Assumptions!C60 -> 21100 | E19: =Assumptions!D60 -> 22000 | F19: =Assumptions!E60 -> 23000 | G19: =Assumptions!F60 -> 24100
A20: Total Current Liabilities | B20: 25800 | C20: =C18+C19 -> 26587.638 | D20: =D18+D19 -> 27612.707 | E20: =E18+E19 -> 28951.507 | F20: =F18+F19 -> 30416.86 | G20: =G18+G19 -> 31965.007
A21: Lease Liabilities (NCL) | B21: 8200 | C21: =Assumptions!B61 -> 8400 | D21: =Assumptions!C61 -> 8600 | E21: =Assumptions!D61 -> 8600 | F21: =Assumptions!E61 -> 8800 | G21: =Assumptions!F61 -> 8800
A22: Other Non-Current Liabilities | B22: 7555 | C22: =Assumptions!B62 -> 7800 | D22: =Assumptions!C62 -> 8050 | E22: =Assumptions!D62 -> 8300 | F22: =Assumptions!E62 -> 8550 | G22: =Assumptions!F62 -> 8800
A23: Total Non-Current Liabilities | B23: 15755 | C23: =C21+C22 -> 16200 | D23: =D21+D22 -> 16650 | E23: =E21+E22 -> 16900 | F23: =F21+F22 -> 17350 | G23: =G21+G22 -> 17600
A24: TOTAL LIABILITIES | B24: 41555 | C24: =C20+C23 -> 42787.638 | D24: =D20+D23 -> 44262.707 | E24: =E20+E23 -> 45851.507 | F24: =F20+F23 -> 47766.86 | G24: =G20+G23 -> 49565.007
A26: EQUITY
A27: Share Capital | B27: 2072 | C27: =Assumptions!B63 -> 2072 | D27: =Assumptions!C63 -> 2072 | E27: =Assumptions!D63 -> 2072 | F27: =Assumptions!E63 -> 2072 | G27: =Assumptions!F63 -> 2072
A28: Reserves & Surplus | B28: 73745 | C28: =B28 + IS_Forecast!C19 + CFS_Forecast!C18 + CFS_Forecast!C19 -> 86347.524 | D28: =C28 + IS_Forecast!D19 + CFS_Forecast!D18 + CFS_Forecast!D19 -> 95109.508 | E28: =D28 + IS_Forecast!E19 + CFS_Forecast!E18 + CFS_Forecast!E19 -> 110251.6 | F28: =E28 + IS_Forecast!F19 + CFS_Forecast!F18 + CFS_Forecast!F19 -> 121763.03 | G28: =F28 + IS_Forecast!G19 + CFS_Forecast!G18 + CFS_Forecast!G19 -> 139542.03
A29: Total Equity | B29: 75817 | C29: =C27+C28 -> 88419.524 | D29: =D27+D28 -> 97181.508 | E29: =E27+E28 -> 112323.6 | F29: =F27+F28 -> 123835.03 | G29: =G27+G28 -> 141614.03
A30: TOTAL LIABILITIES + EQUITY | B30: 117372 | C30: =C24+C29 -> 131207.16 | D30: =D24+D29 -> 141444.22 | E30: =E24+E29 -> 158175.11 | F30: =F24+F29 -> 171601.89 | G30: =G24+G29 -> 191179.04
A32: BALANCE CHECK (TA − TL − TE) | B32: 0 | C32: =C15-C24-C29 -> 0 | D32: =D15-D24-D29 -> 0 | E32: =E15-E24-E29 -> 0 | F32: =F15-F24-F29 -> 0 | G32: =G15-G24-G29 -> 0

Sheet CFS_Forecast
A1: CASH FLOW STATEMENT FORECAST
A2: ₹ Crores
B3: FY2024A | C3: FY2025E | D3: FY2026E | E3: FY2027E | F3: FY2028E | G3: FY2029E
A4: OPERATING ACTIVITIES
A5: Net Income | B5: 26233 | C5: =IS_Forecast!C19 -> 28005.608 | D5: =IS_Forecast!D19 -> 30582.188 | E5: =IS_Forecast!E19 -> 33649.089 | F5: =IS_Forecast!F19 -> 36692.067 | G5: =IS_Forecast!G19 -> 39508.902
A6: (+) D&A (add-back) | B6: 4490 | C6: =-IS_Forecast!C12 -> 4771.4535 | D6: =-IS_Forecast!D12 -> 5057.7407 | E6: =-IS_Forecast!E12 -> 5437.0713 | F6: =-IS_Forecast!F12 -> 5623.744 | G6: =-IS_Forecast!G12 -> 5989.2874
A7: (+) Stock-Based Compensation | B7: 680 | C7: =Assumptions!B21 -> 720 | D7: =Assumptions!B21 -> 720 | E7: =Assumptions!B21 -> 720 | F7: =Assumptions!B21 -> 720 | G7: =Assumptions!B21 -> 720
A8: (−) Change in Working Capital | B8: -4007 | C8: =-((BS_Forecast!C7-BS_Forecast!B7)-(BS_Forecast!C18-BS_Forecast!B18)+(BS_Forecast!C8-BS_Forecast!B8)) -> -382.8512 | D8: =-((BS_Forecast!D7-BS_Forecast!C7)-(BS_Forecast!D18-BS_Forecast!C18)+(BS_Forecast!D8-BS_Forecast!C8)) -> -2075.5605 | E8: =-((BS_Forecast!E7-BS_Forecast!D7)-(BS_Forecast!E18-BS_Forecast!D18)+(BS_Forecast!E8-BS_Forecast!D8)) -> -2742.0345 | F8: =-((BS_Forecast!F7-BS_Forecast!E7)-(BS_Forecast!F18-BS_Forecast!E18)+(BS_Forecast!F8-BS_Forecast!E8)) -> -2726.083 | G8: =-((BS_Forecast!G7-BS_Forecast!F7)-(BS_Forecast!G18-BS_Forecast!F18)+(BS_Forecast!G8-BS_Forecast!F8)) -> -2722.7741
A9: Cash from Operations (CFO) | B9: 27396 | C9: =SUM(C5:C8) -> 33114.211 | D9: =SUM(D5:D8) -> 34284.368 | E9: =SUM(E5:E8) -> 37064.126 | F9: =SUM(F5:F8) -> 40309.728 | G9: =SUM(G5:G8) -> 43495.415
A11: INVESTING ACTIVITIES
A12: Capital Expenditure | B12: -3835 | C12: =-IS_Forecast!C4*Assumptions!B25 -> -4294.3081 | D12: =-IS_Forecast!D4*Assumptions!C25 -> -4383.3753 | E12: =-IS_Forecast!E4*Assumptions!D25 -> -4712.1284 | F12: =-IS_Forecast!F4*Assumptions!E25 -> -4848.0552 | G12: =-IS_Forecast!G4*Assumptions!F25 -> -5163.1788
A13: Investments (net purchases) | B13: -4350 | C13: =-(BS_Forecast!C6-BS_Forecast!B6) -> -1065.2 | D13: =-(BS_Forecast!D6-BS_Forecast!C6) -> -1150.416 | E13: =-(BS_Forecast!E6-BS_Forecast!D6) -> -1242.4493 | F13: =-(BS_Forecast!F6-BS_Forecast!E6) -> -1341.8452 | G13: =-(BS_Forecast!G6-BS_Forecast!F6) -> -1449.1928
A14: Acquisitions | B14: -150 | C14: =-Assumptions!B65 -> -200 | D14: =-Assumptions!C65 -> -300 | E14: =-Assumptions!D65 -> -200 | F14: =-Assumptions!E65 -> -250 | G14: =-Assumptions!F65 -> -200
A15: Cash from Investing (CFI) | B15: -8335 | C15: =SUM(C12:C14) -> -5559.5082 | D15: =SUM(D12:D14) -> -5833.7913 | E15: =SUM(E12:E14) -> -6154.5777 | F15: =SUM(F12:F14) -> -6439.9004 | G15: =SUM(G12:G14) -> -6812.3716
A17: FINANCING ACTIVITIES
A18: Dividends Paid | B18: -12640 | C18: =-IS_Forecast!C19*Assumptions!B35 -> -15403.085 | D18: =-IS_Forecast!D19*Assumptions!B35 -> -16820.203 | E18: =-IS_Forecast!E19*Assumptions!B35 -> -18506.999 | F18: =-IS_Forecast!F19*Assumptions!B35 -> -20180.637 | G18: =-IS_Forecast!G19*Assumptions!B35 -> -21729.896
A19: Share Buybacks | B19: -4510 | C19: =-Assumptions!B36 -> 0 | D19: =-Assumptions!B37 -> -5000 | E19: =-Assumptions!B38 -> 0 | F19: =-Assumptions!B39 -> -5000 | G19: =-Assumptions!B40 -> 0
A20: Lease Payments & Others | B20: -2450 | C20: =-Assumptions!B64 -> -2542 | D20: =-Assumptions!C64 -> -2526 | E20: =-Assumptions!D64 -> -2721 | F20: =-Assumptions!E64 -> -3546 | G20: =-Assumptions!F64 -> -2477
A21: Cash from Financing (CFF) | B21: -19600 | C21: =SUM(C18:C20) -> -17945.085 | D21: =SUM(D18:D20) -> -24346.203 | E21: =SUM(E18:E20) -> -21227.999 | F21: =SUM(F18:F20) -> -28726.637 | G21: =SUM(G18:G20) -> -24206.896
A23: FX & Other Adjustments | B23: 2995 | C23: =BS_Forecast!C5-(C25+C9+C15+C21) -> 2281 | D23: =BS_Forecast!D5-(D25+D9+D15+D21) -> 2356 | E23: =BS_Forecast!E5-(E25+E9+E15+E21) -> 2451 | F23: =BS_Forecast!F5-(F25+F9+F15+F21) -> 3376 | G23: =BS_Forecast!G5-(G25+G9+G15+G21) -> 2157
A24: Net Change in Cash | B24: -539 | C24: =C9+C15+C21+C23 -> 11890.618 | D24: =D9+D15+D21+D23 -> 6460.3736 | E24: =E9+E15+E21+E23 -> 12132.549 | F24: =F9+F15+F21+F23 -> 8519.1909 | G24: =G9+G15+G21+G23 -> 14633.148
A25: Opening Cash | B25: 12547 | C25: =BS_Forecast!B5 -> 15003 | D25: =C26 -> 26893.618 | E25: =D26 -> 33353.992 | F25: =E26 -> 45486.541 | G25: =F26 -> 54005.731
A26: Closing Cash | B26: 15003 | C26: =C25+C24 -> 26893.618 | D26: =D25+D24 -> 33353.992 | E26: =E25+E24 -> 45486.541 | F26: =F25+F24 -> 54005.731 | G26: =G25+G24 -> 68638.879
A28: FREE CASH FLOW (CFO − CapEx) | B28: 23561 | C28: =C9+C12 -> 28819.903 | D28: =D9+D12 -> 29900.993 | E28: =E9+E12 -> 32351.997 | F28: =F9+F12 -> 35461.673 | G28: =G9+G12 -> 38332.236
A29: FCF Margin (%) | B29: 0.153 | C29: =C28/IS_Forecast!C4 -> 0.18120203 | D29: =D28/IS_Forecast!D4 -> 0.17735781 | E29: =E28/IS_Forecast!E4 -> 0.17850785 | F29: =F28/IS_Forecast!F4 -> 0.18286546 | G29: =G28/IS_Forecast!G4 -> 0.18560386
A30: FCF / Net Income (%) | B30: 0.898 | C30: =C28/C5 -> 1.0290761 | D30: =D28/D5 -> 0.97772576 | E30: =E28/E5 -> 0.9614524 | F30: =F28/F5 -> 0.96646703 | G30: =G28/G5 -> 0.97021771

Sheet DCF_Valuation
A1: DCF VALUATION - INFOSYS LTD
A2: ₹ Crores (Unless stated)
B3: FY2025E | C3: FY2026E | D3: FY2027E | E3: FY2028E | F3: FY2029E
A5: SECTION 1: FCFF BRIDGE
A6: EBIT | B6: =IS_Forecast!C13 -> 34195.417 | C6: =IS_Forecast!D13 -> 37427.281 | D6: =IS_Forecast!E13 -> 41321.742 | E6: =IS_Forecast!F13 -> 45183.875 | F6: =IS_Forecast!G13 -> 48740.408
A7: Tax Rate (%) | B7: =Assumptions!B20 -> 0.26 | C7: =Assumptions!B20 -> 0.26 | D7: =Assumptions!B20 -> 0.26 | E7: =Assumptions!B20 -> 0.26 | F7: =Assumptions!B20 -> 0.26
A8: NOPAT (EBIT * (1-T)) | B8: =B6*(1-B7) -> 25304.608 | C8: =C6*(1-C7) -> 27696.188 | D8: =D6*(1-D7) -> 30578.089 | E8: =E6*(1-E7) -> 33436.067 | F8: =F6*(1-F7) -> 36067.902
A9: (+) D&A Add-Back | B9: =-IS_Forecast!C12 -> 4771.4535 | C9: =-IS_Forecast!D12 -> 5057.7407 | D9: =-IS_Forecast!E12 -> 5437.0713 | E9: =-IS_Forecast!F12 -> 5623.744 | F9: =-IS_Forecast!G12 -> 5989.2874
A10: (-) Capital Expenditure | B10: =CFS_Forecast!C12 -> -4294.3081 | C10: =CFS_Forecast!D12 -> -4383.3753 | D10: =CFS_Forecast!E12 -> -4712.1284 | E10: =CFS_Forecast!F12 -> -4848.0552 | F10: =CFS_Forecast!G12 -> -5163.1788
A11: (-) Change in Working Capital | B11: =CFS_Forecast!C8 -> -382.8512 | C11: =CFS_Forecast!D8 -> -2075.5605 | D11: =CFS_Forecast!E8 -> -2742.0345 | E11: =CFS_Forecast!F8 -> -2726.083 | F11: =CFS_Forecast!G8 -> -2722.7741
A12: Free Cash Flow to Firm (FCFF) | B12: =SUM(B8:B11) -> 25398.903 | C12: =SUM(C8:C11) -> 26294.993 | D12: =SUM(D8:D11) -> 28560.997 | E12: =SUM(E8:E11) -> 31485.673 | F12: =SUM(F8:F11) -> 34171.236
A14: SECTION 2: DISCOUNTING
A15: WACC | B15: =Assumptions!B49 -> 0.12525
A16: Mid-Year Convention Toggle (1=Yes, 0=No) | B16: 1
A17: Discount Period Adjustment | B17: =B16*0.5 -> 0.5
A19: Discount Period | B19: =1-$B$17 -> 0.5 | C19: =2-$B$17 -> 1.5 | D19: =3-$B$17 -> 2.5 | E19: =4-$B$17 -> 3.5 | F19: =5-$B$17 -> 4.5
A20: Discount Factor | B20: =1/((1+$B$15)^B19) -> 0.9427043 | C20: =1/((1+$B$15)^C19) -> 0.83777321 | D20: =1/((1+$B$15)^D19) -> 0.74452185 | E20: =1/((1+$B$15)^E19) -> 0.66165016 | F20: =1/((1+$B$15)^F19) -> 0.58800281
A21: PV of FCFF | B21: =B12*B20 -> 23943.655 | C21: =C12*C20 -> 22029.241 | D21: =D12*D20 -> 21264.286 | E21: =E12*E20 -> 20832.501 | F21: =F12*F20 -> 20092.783
A22: Sum of PV of FCFFs | B22: =SUM(B21:F21) -> 108162.47 | C22: =SUM(C21:G21) -> 84218.811 | D22: =SUM(D21:H21) -> 62189.57 | E22: =SUM(E21:I21) -> 40925.284 | F22: =SUM(F21:J21) -> 20092.783
A24: SECTION 3: TERMINAL VALUE
A25: Terminal Growth Rate (g) | B25: =Assumptions!B50 -> 0.045
A26: Exit EV/EBITDA Multiple | B26: =Assumptions!B53 -> 22
A27: Terminal Year FCFF | B27: =F12*(1+B25) -> 35708.942
A29: METHOD 1: GORDON GROWTH MODEL
A30: Terminal Value | B30: =B27/(B15-B25) -> 444971.24
A31: Terminal Year Discount Fcator | B31: =1/((1+$B$15)^F19) -> 0.58800281
A32: PV of Terminal Value (GGM) | B32: =B30*B31 -> 261644.34
A34: METHOD 2: EXIT MULTIPLE
A35: Terminal Year EBITDA | B35: =IS_Forecast!G10 -> 54729.695
A36: Terminal Value (Exit Multiple) | B36: =B35*B26 -> 1204053.3
A37: PV of Terminal Value (Exit Multiple) | B37: =B36*B31 -> 707986.72
A39: RECONCILIATION
A40: Implied EV/EBITDA (from GGM) | B40: =B30/B35 -> 8.1303438
A42: TV as % of Total EV (GGM) | B42: =B32/(B22+B32) -> 0.70751629
A43: TV as % of Total Ev (Exit Multiple) | B43: =B37/(B22+B37) -> 0.86747219
A45: SECTION 4: EV -> EQUITY BRIDGE
A46: Sum of PV of FCFFs | B46: =B22 -> 108162.47
A47: (+) PV of Terminal Value (GGM) | B47: =B32 -> 261644.34
A48: Enterprise Value (GGM) | B48: =B46+B47 -> 369806.81
A49: (+)PV of Terminal Value (Exit Multiple) | B49: =B37 -> 707986.72
...

Sheet Comps
A1: COMPARABLE COMPANY ANALYSIS - IT SERVICES
A2: Market data as of March 2026 | Financials in local currency unless stated
A3: Source: BSE/NSE filings, company reports
A5: Company | B5: Ticker | C5: Currency | D5: Market Cap | E5: Enterprise Value | F5: Revenue LTM | G5: EBITDA LTM | H5: EBIT LTM | I5: Net Income LTM | J5: EV/Revenue | K5: EV/EBITDA | L5: EV/EBIT | M5: P/E | N5: FCF Yield | O5: Revenue Growth | P5: EBITDA Margin
D6: (₹ Cr / $ Bn) | E6: (₹ Cr / $ Bn) | F6: (₹ Cr / $ Bn) | G6: (₹ Cr / $ Bn) | H6: (₹ Cr / $ Bn) | I6: (₹ Cr / $ Bn) | J6: (x) | K6: (x) | L6: (x) | M6: (x) | N6: (%) | O6: (%) | P6: (%)
A8: Infosys Ltd | B8: INFY | C8: INR | D8: =Assumptions!B51*Assumptions!B52 -> 664000 | E8: =D8-(BS_Forecast!B5+BS_Forecast!B6) -> 635682 | F8: =IS_Forecast!B4 -> 153670 | G8: =IS_Forecast!B10 -> 32515 | H8: =IS_Forecast!B13 -> 28025 | I8: =IS_Forecast!B19 -> 21743 | J8: =E8/F8 -> 4.1366695 | K8: =E8/G8 -> 19.550423 | L8: =E8/H8 -> 22.682676 | M8: =D8/I8 -> 30.538564 | N8: =CFS_Forecast!B28/D8 -> 0.035483434 | O8: =IS_Forecast!B5 -> 0.047033734 | P8: =IS_Forecast!B11 -> 0.21158977
A9: Tata Consultancy Services | B9: TCS | C9: INR | D9: 1385000 | E9: 1368000 | F9: 240893 | G9: 62800 | H9: 58200 | I9: 46099 | J9: =E9/F9 -> 5.6788699 | K9: =E9/G9 -> 21.783439 | L9: =E9/H9 -> 23.505155 | M9: =D9/I9 -> 30.044036 | N9: 0.028 | O9: 0.047 | P9: =G9/F9 -> 0.26069666
A10: HCL Technologies | B10: HCLTECH | C10: INR | D10: 485000 | E10: 472000 | F10: 109913 | G10: 24400 | H10: 21800 | I10: 15710 | J10: =E10/F10 -> 4.2943055 | K10: =E10/G10 -> 19.344262 | L10: =E10/H10 -> 21.651376 | M10: =D10/I10 -> 30.872056 | N10: 0.031 | O10: 0.55 | P10: =G10/F10 -> 0.22199376
A11: Wipro Ltd | B11: WIPRO | C11: INR | D11: 263000 | E11: 256000 | F11: 89807 | G11: 18200 | H11: 15900 | I11: 11127 | J11: =E11/F11 -> 2.8505573 | K11: =E11/G11 -> 14.065934 | L11: =E11/H11 -> 16.100629 | M11: =D11/I11 -> 23.6362 | N11: 0.035 | O11: 0.015 | P11: =G11/F11 -> 0.20265681
A12: Accenture plc | B12: ACN | C12: USD | D12: 197 | E12: 195 | F12: 64.9 | G12: 11.2 | H12: 9.8 | I12: 7.26 | J12: =E12/F12 -> 3.0046225 | K12: =E12/G12 -> 17.410714 | L12: =E12/H12 -> 19.897959 | M12: =D12/I12 -> 27.134986 | N12: 0.033 | O12: 0.042 | P12: =G12/F12 -> 0.17257319
A13: Cognizant Technology | B13: CTSH | C13: USD | D13: 35 | E13: 34 | F13: 19.7 | G13: 3.8 | H13: 3.3 | I13: 2.18 | J13: =E13/F13 -> 1.7258883 | K13: =E13/G13 -> 8.9473684 | L13: =E13/H13 -> 10.30303 | M13: =D13/I13 -> 16.055046 | N13: 0.04 | O13: 0.02 | P13: =G13/F13 -> 0.1928934
A15: Mean (ex. Subject) | J15: =AVERAGE(J9:J13) -> 3.5108487 | K15: =AVERAGE(K9:K13) -> 16.310344 | L15: =AVERAGE(L9:L13) -> 18.29163 | M15: =AVERAGE(M9:M13) -> 25.548465 | N15: =AVERAGE(N9:N13) -> 0.0334 | O15: =AVERAGE(O9:O13) -> 0.1348 | P15: =AVERAGE(P9:P13) -> 0.21016276
A16: Median (ex. Subject) | J16: =MEDIAN(J9:J13) -> 3.0046225 | K16: =MEDIAN(K9:K13) -> 17.410714 | L16: =MEDIAN(L9:L13) -> 19.897959 | M16: =MEDIAN(M9:M13) -> 27.134986 | N16: =MEDIAN(N9:N13) -> 0.033 | O16: =MEDIAN(O9:O13) -> 0.042 | P16: =MEDIAN(P9:P13) -> 0.20265681
A17: 25th Percentile | J17: =QUARTILE(J9:J13,1) -> 2.8505573 | K17: =QUARTILE(K9:K13,1) -> 14.065934 | L17: =QUARTILE(L9:L13,1) -> 16.100629 | M17: =QUARTILE(M9:M13,1) -> 23.6362
A18: 75th Percentile | J18: =QUARTILE(J9:J13,3) -> 4.2943055 | K18: =QUARTILE(K9:K13,3) -> 19.344262 | L18: =QUARTILE(L9:L13,3) -> 21.651376 | M18: =QUARTILE(M9:M13,3) -> 30.044036
A19: INFOSYS (Subject)
A20: Premium / (Discount) to Mean | J20: =J8 -> 4.1366695 | K20: =K8 -> 19.550423 | L20: =L8 -> 22.682676 | M20: =M8 -> 30.538564 | N20: =N8 -> 0.035483434 | O20: =O8 -> 0.047033734 | P20: =P8 -> 0.21158977
A21: Premium / (Discount) to Median | J21: =J20/J15-1 -> 0.17825342 | K21: =K20/K15-1 -> 0.1986518 | L21: =L20/L15-1 -> 0.24005769 | M21: =M20/M15-1 -> 0.19531895
J22: =J20/J16-1 -> 0.37676846 | K22: =K20/K16-1 -> 0.12289608 | L22: =L20/L16-1 -> 0.13994988 | M22: =M20/M16-1 -> 0.12543135
A24: IMPLIED VALUATION FROM COMPS
A25: Metric | B25: Peer Mean Multiple | C25: Peer Median Multiple | D25: Implied EV (₹ Cr) | E25: Implied Equity Value (₹ Cr) | F25: Implied Price per Share (₹) | G25: Upside / (Downside) vs CMP
A26: EV/EBITDA | B26: =K15 -> 16.310344 | C26: =K16 -> 17.410714 | D26: =C26*G8 -> 566109.38 | E26: =D26+BS_Forecast!B5+BS_Forecast!B6 -> 594427.38 | F26: =E26/Assumptions!B51 -> 1432.3551 | G26: =F26/Assumptions!B52-1 -> -0.10477805
A27: EV/EBIT | B27: =L15 -> 18.29163 | C27: =L16 -> 19.897959 | D27: =C27*H8 -> 557640.31 | E27: =D27+BS_Forecast!B5+BS_Forecast!B6 -> 585958.31 | F27: =E27/Assumptions!B51 -> 1411.9477 | G27: =F27/Assumptions!B52-1 -> -0.11753267
A28: P/E | B28: =M15 -> 25.548465 | C28: =M16 -> 27.134986 | E28: =C28*I8 -> 589996.01 | F28: =E28/Assumptions!B51 -> 1421.6771 | G28: =F28/Assumptions!B52-1 -> -0.1114518

Sheet Credit_Metrics
A1: CREDIT METRICS DASHBOARD - INFOSYS LTD
A2: ₹ Crores | IFRS Consolidated | FY2024A-FY2029E
B4: FY2024A | C4: FY2025E | D4: FY2026E | E4: FY2027E | F4: FY2028E | G4: FY2029E
A6: BLOCK 1: LIQUIDITY
A7: Current Ratio | B7: =BS_Forecast!B9/BS_Forecast!B20 -> 2.6224031 | C7: =BS_Forecast!C9/BS_Forecast!C20 -> 3.0572218 | D7: =BS_Forecast!D9/BS_Forecast!D20 -> 3.3062939 | E7: =BS_Forecast!E9/BS_Forecast!E20 -> 3.7252486 | F7: =BS_Forecast!F9/BS_Forecast!F20 -> 3.9749017 | G7: =BS_Forecast!G9/BS_Forecast!G20 -> 4.3847102
A8: Quick Ratio (ex. Inventory) | B8: =(BS_Forecast!B9)/BS_Forecast!B20 -> 2.6224031 | C8: =(BS_Forecast!C9)/BS_Forecast!C20 -> 3.0572218 | D8: =(BS_Forecast!D9)/BS_Forecast!D20 -> 3.3062939 | E8: =(BS_Forecast!E9)/BS_Forecast!E20 -> 3.7252486 | F8: =(BS_Forecast!F9)/BS_Forecast!F20 -> 3.9749017 | G8: =(BS_Forecast!G9)/BS_Forecast!G20 -> 4.3847102 | H8: "No Inventory"
A9: Net Cash Position (₹ Cr) | B9: =BS_Forecast!B5+BS_Forecast!B6 -> 28318 | C9: =BS_Forecast!C5+BS_Forecast!C6 -> 41273.818 | D9: =BS_Forecast!D5+BS_Forecast!D6 -> 48884.608 | E9: =BS_Forecast!E5+BS_Forecast!E6 -> 62259.606 | F9: =BS_Forecast!F5+BS_Forecast!F6 -> 72120.642 | G9: =BS_Forecast!G5+BS_Forecast!G6 -> 88202.982
A10: Net Cash / EBITDA | B10: =B9/IS_Forecast!B10 -> 0.87092111 | C10: =C9/IS_Forecast!C10 -> 1.0592028 | D10: =D9/IS_Forecast!D10 -> 1.1506316 | E10: =E9/IS_Forecast!E10 -> 1.3315053 | F10: =F9/IS_Forecast!F10 -> 1.4194848 | G10: =G9/IS_Forecast!G10 -> 1.6116111
A11: Cash & Investments (₹ Cr) | B11: =B9 -> 28318 | C11: =C9 -> 41273.818 | D11: =D9 -> 48884.608 | E11: =E9 -> 62259.606 | F11: =F9 -> 72120.642 | G11: =G9 -> 88202.982
A12: Cash as % of Total Assets | B12: =B11/BS_Forecast!B15 -> 0.24126708 | C12: =C11/BS_Forecast!C15 -> 0.31456985 | D12: =D11/BS_Forecast!D15 -> 0.34561051 | E12: =E11/BS_Forecast!E15 -> 0.39361191 | F12: =F11/BS_Forecast!F15 -> 0.42027883 | G12: =G11/BS_Forecast!G15 -> 0.46136324
A14: BLOCK 2: COVERAGE
A15: Interest Coverage (EBIT / Interest) | B15: =IF(0=0,"N/M (Zero Debt)",0) -> N/M (Zero Debt) | C15: ="N/M — Zero Debt" -> N/M — Zero Debt | D15: ="N/M — Zero Debt" -> N/M — Zero Debt | E15: ="N/M — Zero Debt" -> N/M — Zero Debt | F15: ="N/M — Zero Debt" -> N/M — Zero Debt | G15: ="N/M — Zero Debt" -> N/M — Zero Debt
A16: Debt Service Coverage (EBITDA / Total Debt) | B16: ="N/M — Zero Debt" -> N/M — Zero Debt | C16: ="N/M — Zero Debt" -> N/M — Zero Debt | D16: ="N/M — Zero Debt" -> N/M — Zero Debt | E16: ="N/M — Zero Debt" -> N/M — Zero Debt | F16: ="N/M — Zero Debt" -> N/M — Zero Debt | G16: ="N/M — Zero Debt" -> N/M — Zero Debt
A17: FCF Coverage of Dividends | B17: =CFS_Forecast!B28/ABS(CFS_Forecast!B18) -> 1.8640032 | C17: =CFS_Forecast!C28/ABS(CFS_Forecast!C18) -> 1.8710475 | D17: =CFS_Forecast!D28/ABS(CFS_Forecast!D18) -> 1.7776832 | E17: =CFS_Forecast!E28/ABS(CFS_Forecast!E18) -> 1.7480953 | F17: =CFS_Forecast!F28/ABS(CFS_Forecast!F18) -> 1.7572128 | G17: =CFS_Forecast!G28/ABS(CFS_Forecast!G18) -> 1.7640322
A18: FCF Coverage of Total Capital Returns | B18: =CFS_Forecast!B28/(ABS(CFS_Forecast!B18)+ABS(CFS_Forecast!B19)) -> 1.3738192 | C18: =CFS_Forecast!C28/(ABS(CFS_Forecast!C18)+ABS(CFS_Forecast!C19)) -> 1.8710475 | D18: =CFS_Forecast!D28/(ABS(CFS_Forecast!D18)+ABS(CFS_Forecast!D19)) -> 1.3703352 | E18: =CFS_Forecast!E28/(ABS(CFS_Forecast!E18)+ABS(CFS_Forecast!E19)) -> 1.7480953 | F18: =CFS_Forecast!F28/(ABS(CFS_Forecast!F18)+ABS(CFS_Forecast!F19)) -> 1.4082913 | G18: =CFS_Forecast!G28/(ABS(CFS_Forecast!G18)+ABS(CFS_Forecast!G19)) -> 1.7640322
A20: BLOCK 3: CAPITAL STRUCTURE
A21: Total Financial Debt (₹ Cr) | B21: 0 | C21: 0 | D21: 0 | E21: 0 | F21: 0 | G21: 0 | H21: "Zero financial debt - Infosys is debt free"
A22: Total Equity (₹ Cr) | B22: =BS_Forecast!B29 -> 75817 | C22: =BS_Forecast!C29 -> 88419.524 | D22: =BS_Forecast!D29 -> 97181.508 | E22: =BS_Forecast!E29 -> 112323.6 | F22: =BS_Forecast!F29 -> 123835.03 | G22: =BS_Forecast!G29 -> 141614.03
A23: Debt / Equity | B23: =IF(B22=0,"N/M",B21/B22) -> 0 | C23: =IF(C22=0,"N/M",C21/C22) -> 0 | D23: =IF(D22=0,"N/M",D21/D22) -> 0 | E23: =IF(E22=0,"N/M",E21/E22) -> 0 | F23: =IF(F22=0,"N/M",F21/F22) -> 0 | G23: =IF(G22=0,"N/M",G21/G22) -> 0
A24: Debt / Total Capital | B24: =B21/(B21+B22) -> 0 | C24: =C21/(C21+C22) -> 0 | D24: =D21/(D21+D22) -> 0 | E24: =E21/(E21+E22) -> 0 | F24: =F21/(F21+F22) -> 0 | G24: =G21/(G21+G22) -> 0
A25: Equity / Total Assets | B25: =B22/BS_Forecast!B15 -> 0.64595474 | C25: =C22/BS_Forecast!C15 -> 0.67389251 | D25: =D22/BS_Forecast!D15 -> 0.68706598 | E25: =E22/BS_Forecast!E15 -> 0.71012185 | F25: =F22/BS_Forecast!F15 -> 0.72164141 | G25: =G22/BS_Forecast!G15 -> 0.74074037
A27: BLOCK 4: CASH RETURNS
A28: Dividend Yield (%) | B28: =ABS(CFS_Forecast!B18)/(Assumptions!B51*Assumptions!B52) -> 0.019036145 | C28: =ABS(CFS_Forecast!C18)/(Assumptions!B51*Assumptions!B52) -> 0.023197417 | D28: =ABS(CFS_Forecast!D18)/(Assumptions!B51*Assumptions!B52) -> 0.025331632 | E28: =ABS(CFS_Forecast!E18)/(Assumptions!B51*Assumptions!B52) -> 0.027871986 | F28: =ABS(CFS_Forecast!F18)/(Assumptions!B51*Assumptions!B52) -> 0.030392526 | G28: =ABS(CFS_Forecast!G18)/(Assumptions!B51*Assumptions!B52) -> 0.032725747
A29: Buyback Yield (%) | B29: =ABS(CFS_Forecast!B19)/(Assumptions!B51*Assumptions!B52) -> 0.0067921687 | C29: =ABS(CFS_Forecast!C19)/(Assumptions!B51*Assumptions!B52) -> 0 | D29: =ABS(CFS_Forecast!D19)/(Assumptions!B51*Assumptions!B52) -> 0.0075301205 | E29: =ABS(CFS_Forecast!E19)/(Assumptions!B51*Assumptions!B52) -> 0 | F29: =ABS(CFS_Forecast!F19)/(Assumptions!B51*Assumptions!B52) -> 0.0075301205 | G29: =ABS(CFS_Forecast!G19)/(Assumptions!B51*Assumptions!B52) -> 0
A30: Total Shareholder Yield (%) | B30: =B28+B29 -> 0.025828313 | C30: =C28+C29 -> 0.023197417 | D30: =D28+D29 -> 0.032861752 | E30: =E28+E29 -> 0.027871986 | F30: =F28+F29 -> 0.037922646 | G30: =G28+G29 -> 0.032725747
A31: Dividend Payout Ratio (%) | B31: =ABS(CFS_Forecast!B18)/IS_Forecast!B19 -> 0.58133652 | C31: =ABS(CFS_Forecast!C18)/IS_Forecast!C19 -> 0.55 | D31: =ABS(CFS_Forecast!D18)/IS_Forecast!D19 -> 0.55 | E31: =ABS(CFS_Forecast!E18)/IS_Forecast!E19 -> 0.55 | F31: =ABS(CFS_Forecast!F18)/IS_Forecast!F19 -> 0.55 | G31: =ABS(CFS_Forecast!G18)/IS_Forecast!G19 -> 0.55
A32: FCF Payout Ratio (%) | B32: =ABS(CFS_Forecast!B18)/CFS_Forecast!B28 -> 0.53647978 | C32: =ABS(CFS_Forecast!C18)/CFS_Forecast!C28 -> 0.53445998 | D32: =ABS(CFS_Forecast!D18)/CFS_Forecast!D28 -> 0.56252993 | E32: =ABS(CFS_Forecast!E18)/CFS_Forecast!E28 -> 0.5720512 | F32: =ABS(CFS_Forecast!F18)/CFS_Forecast!F28 -> 0.56908305 | G32: =ABS(CFS_Forecast!G18)/CFS_Forecast!G28 -> 0.56688307
A34: BLOCK 5: DUPONT ANALYSIS
A35: Net Profit Margin (%) | B35: =IS_Forecast!B19/IS_Forecast!B4 -> 0.14149151 | C35: =IS_Forecast!C19/IS_Forecast!C4 -> 0.17608225 | D35: =IS_Forecast!D19/IS_Forecast!D4 -> 0.18139832 | E35: =IS_Forecast!E19/IS_Forecast!E4 -> 0.18566478 | F35: =IS_Forecast!F19/IS_Forecast!F4 -> 0.18921024 | G35: =IS_Forecast!G19/IS_Forecast!G4 -> 0.19130125
A36: Asset Turnover (x) | B36: =IS_Forecast!B4/BS_Forecast!B15 -> 1.309256 | C36: =IS_Forecast!C4/BS_Forecast!C15 -> 1.2121934 | D36: =IS_Forecast!D4/BS_Forecast!D15 -> 1.1919283 | E36: =IS_Forecast!E4/BS_Forecast!E15 -> 1.1457916 | F36: =IS_Forecast!F4/BS_Forecast!F15 -> 1.1300704 | G36: =IS_Forecast!G4/BS_Forecast!G15 -> 1.0802813
A37: Equity Multiplier (x) | B37: =BS_Forecast!B15/BS_Forecast!B29 -> 1.5480961 | C37: =BS_Forecast!C15/BS_Forecast!C29 -> 1.4839162 | D37: =BS_Forecast!D15/BS_Forecast!D29 -> 1.4554643 | E37: =BS_Forecast!E15/BS_Forecast!E29 -> 1.408209 | F37: =BS_Forecast!F15/BS_Forecast!F29 -> 1.3857298 | G37: =BS_Forecast!G15/BS_Forecast!G29 -> 1.3500007
A38: Return on Equity - DuPont (%) | B38: =B35*B36*B37 -> 0.28678265 | C38: =C35*C36*C37 -> 0.31673557 | D38: =D35*D36*D37 -> 0.31469143 | E38: =E35*E36*E37 -> 0.29957275 | F38: =F35*F36*F37 -> 0.29629797 | G38: =G35*G36*G37 -> 0.27899002
A39: Return on Equity - Direct (%) | B39: =IS_Forecast!B19/BS_Forecast!B29 -> 0.28678265 | C39: =IS_Forecast!C19/BS_Forecast!C29 -> 0.31673557 | D39: =IS_Forecast!D19/BS_Forecast!D29 -> 0.31469143 | E39: =IS_Forecast!E19/BS_Forecast!E29 -> 0.29957275 | F39: =IS_Forecast!F19/BS_Forecast!F29 -> 0.29629797 | G39: =IS_Forecast!G19/BS_Forecast!G29 -> 0.27899002
A40: Return on Assets (%) | B40: =IS_Forecast!B19/BS_Forecast!B15 -> 0.18524861 | C40: =IS_Forecast!C19/BS_Forecast!C15 -> 0.21344573 | D40: =IS_Forecast!D19/BS_Forecast!D15 -> 0.21621378 | E40: =IS_Forecast!E19/BS_Forecast!E15 -> 0.21273315 | F40: =IS_Forecast!F19/BS_Forecast!F15 -> 0.21382088 | G40: =IS_Forecast!G19/BS_Forecast!G15 -> 0.20665917
A41: Return on Invested Cpaital (%) | B41: =IS_Forecast!B13*(1-Assumptions!B20)/BS_Forecast!B29 -> 0.27353364 | C41: =IS_Forecast!C13*(1-Assumptions!B20)/BS_Forecast!B29 -> 0.33375903 | D41: =IS_Forecast!D13*(1-Assumptions!B20)/BS_Forecast!B29 -> 0.36530314 | E41: =IS_Forecast!E13*(1-Assumptions!B20)/BS_Forecast!B29 -> 0.40331441 | F41: =IS_Forecast!F13*(1-Assumptions!B20)/BS_Forecast!B29 -> 0.44101016 | G41: =IS_Forecast!G13*(1-Assumptions!B20)/BS_Forecast!B29 -> 0.47572315 | H41: NOPAT / EQUITY (zero debt so IC=Equity)
A43: BLOCK 6: CREDIT SCORECARD
A44: Metric | B44: FY2024A Value | C44: Threshold | D44: Status | E44: Commentary
A45: Current Ratio | B45: =B7 -> 2.6224031 | C45: >1.5x | D45: STRONG | E45: Well above minimum threshold
A46: Net Cash / EBITDA | B46: =B10 -> 0.87092111 | C46: >0x | D46: STRONG | E46: Net cash — zero leverage risk
A47: FCF Coverage of Dividends | B47: =B17 -> 1.8640032 | C47: >1.2x | D47: STRONG | E47: Highly sustainable payout
...

Sheet Sentiment
A1: SENTIMENT ANALYSIS - INFOSYS LTD
A2: Qualitative Research Framework | Updated: March 2026
A3: Sources: NSE/BSE filings, earnings transcripts, Bloomberg, company press releases
A5: BLOCK 1: MANAGEMENT TONE TRACKER
A6: Earnings Call Scoring (Scale: -2 to +2)
B7: Q2 FY2024 | C7: Q3 FY2024 | D7: Q4 FY2024 | E7: Q1 FY2025 | F7: Weight | G7: Weighted Score
A8: Revenue Outlook & Deal Pipeline | B8: -1 | C8: 0 | D8: 1 | E8: 1 | F8: 0.3 | G8: =AVERAGE(B8:E8)*F8 -> 0.075
A9: Margin Guidance & Cost Commentary | B9: 0 | C9: 1 | D9: 1 | E9: 1 | F9: 0.2 | G9: =AVERAGE(B9:E9)*F9 -> 0.15
A10: GenAI / Technology Positioning | B10: 1 | C10: 1 | D10: 2 | E10: 2 | F10: 0.2 | G10: =AVERAGE(B10:E10)*F10 -> 0.3
A11: Client Demand Enviornment | B11: -1 | C11: -1 | D11: 0 | E11: 1 | F11: 0.15 | G11: =AVERAGE(B11:E11)*F11 -> -0.0375
A12: Capital Allocation Signals | B12: 1 | C12: 1 | D12: 1 | E12: 1 | F12: 0.1 | G12: =AVERAGE(B12:E12)*F12 -> 0.1
A13: Overall Management Confidence | B13: 0 | C13: 0 | D13: 1 | E13: 1 | F13: 0.05 | G13: =AVERAGE(B13:E13)*F13 -> 0.025
F14: Sum (must = 1.0) | G14: =SUM(F8:F13) -> 1
A15: Total Management Tone Score | G15: =SUM(G8:G13) -> 0.6125 | H15: =IF(G15>0.5,"POSITIVE",IF(G15<-0.5,"NEGATIVE","NEUTRAL")) -> POSITIVE
A17: BLOCK 2: YOUR ESTIMATES vs CONSENSUS
B18: FY2025E | C18: FY2026E | D18: FY2027E | E18: Your Variant Vieew
A19: Revenue (₹ Cr) - Consensus | B19: 157000 | C19: 167500 | D19: 180000
A20: Revenue (₹ Cr) - Your Model | B20: =IS_Forecast!C4 -> 159048.45 | C20: =IS_Forecast!D4 -> 168591.36 | D20: =IS_Forecast!E4 -> 181235.71
A21: Difference (%) | B21: =B20/B19-1 -> 0.013047452 | C21: =C20/C19-1 -> 0.0065155642 | D21: =D20/D19-1 -> 0.0068650487
A22: EBITDA Margin (%) - Consensus | B22: 0.243 | C22: 0.25 | D22: 0.256
A23: EBITA Margin (%) - Your Model | B23: =IS_Forecast!C11 -> 0.245 | C23: =IS_Forecast!D11 -> 0.252 | D23: =IS_Forecast!E11 -> 0.258
A24: Difference (bps) | B24: =(B23-B22)*10000 -> 20 | C24: =(C23-C22)*10000 -> 20 | D24: =(D23-D22)*10000 -> 20 | E24: "Slightly above consensus - GenAI mix benefits underappreciated
A25: EPS (₹) - Consensus | B25: 63.5 | C25: 69.2 | D25: 76.8
A26: EPS (₹) - Your Model | B26: =IS_Forecast!C19/Assumptions!B51 -> 67.483394 | C26: =IS_Forecast!D19/Assumptions!B51 -> 73.69202 | D26: =IS_Forecast!E19/Assumptions!B51 -> 81.082142
A27: Difference (%) | B27: =B26/B25-1 -> 0.06273061 | C27: =C26/C25-1 -> 0.064913578 | D27: =D26/D25-1 -> 0.055757053 | E27: "Above consensus - margin expansion + buybacks not fully priced in"
A29: BLOCK 3: NEWS & EVENT SENTIMENT TRACKER
A30: Date | B30: Event / Headline | C30: Category | D30: Score (-2 to +2) | E30: Market Priced In? | F30: Analyst Action
A31: 46023 | B31: Q3 FY2026 earnings beat — revenue in-line, margins +40bps vs guidance | C31: Earnings | D31: 1 | E31: Yes | F31: Hold - priced in
A32: 45992 | B32: $2.5Bn mega-deal win with European financial services client | C32: Deal Win | D32: 2 | E32: Partial | F32: Buy - not fully reflected
A33: 45962 | B33: CEO Salil Parekh reaffirmed FY2026 revenue guidance 4.5-5% | C33: Guidance | D33: 1 | E33: Yes | F33: No action
A34: 45931 | B34: Announced GenAI platform partnership with Google Cloud | C34: Strategic | D34: 2 | E34: Partial | F34: Buy - re-rating catalyst
A35: 45901 | B35: US Federal Reserve rate cut — positive for BFSI client capex | C35: Macro | D35: 1 | E35: Partial | F35: Buy
A36: 45870 | B36: Attrition rate declined to 12.3% — lowest in 3 years | C36: Operations | D36: 1 | E36: No | F36: Buy- margin tailwind
A37: 45839 | B37: Weak Q1 FY2026 — revenue missed consensus by 0.8% | C37: Earnings | D37: -1 | E37: Yes | F37: Hold
A38: 45809 | B38: INR appreciation vs USD — ~100bps margin headwind flagged | C38: FX / Macro | D38: -1 | E38: Partial | F38: Watch
A39: 45778 | B39: Buyback announced ₹5,000 Cr at ₹1,750 cap price | C39: Capital Return | D39: 2 | E39: Yes | F39: Hold
A40: 45748 | B40: Large BFSI client reduced discretionary spend for 2 quarters | C40: Demand | D40: -1 | E40: Yes | F40: Hold
A42: Average News Sentiment Score | D42: =AVERAGE(D31:D40) -> 0.7 | E42: =IF(D42>0.3,"NET POSITIVE",IF(D42<-0.3,"NET NEGATIVE","MIXED")) -> NET POSITIVE
A44: BLOCK 4: RISK MATRIX
B45: Risk Factor | C45: Category | D45: Probabaility (1-3) | E45: Impact (1-3) | F45: Risk Score (P*I) | G45: RAG Status | H45: Mitigation
...
